Workbook

Sheet Executive Summary
A1: Executive Summary
A3: ="Polish Housing Market — 17 major cities | Prices: "&src_city_snapshot!$AS$2&" • Affordability & full-year supply: "&src_city_snapshot!$AT$2&" • Current supply update: H1 "&src_city_snapshot!$AW$2&" vs H1 "&(src_city_snapshot!$AW$2-1) -> Polish Housing Market — 17 major cities | Prices: 2026Q2 • Affordability & full-year supply: 2025 • Current supply update: H1 2026 vs H1 2025
A4: Median Secondary Price | D4: Median Primary Price | G4: Median Affordability | J4: Median Completed Supply
A5: =MEDIAN('City Comparison'!B8:B24) -> 9403.1318 | D5: =MEDIAN('City Comparison'!C8:C24) -> 11427.47 | G5: =MEDIAN('City Comparison'!E8:E24) -> 0.95897791 | J5: =MEDIAN('City Comparison'!G8:G24) -> 8.3991882
A8: ="Reference: "&src_city_snapshot!$AS$2 -> Reference: 2026Q2 | D8: ="Reference: "&src_city_snapshot!$AS$2 -> Reference: 2026Q2 | G8: ="Reference: "&src_city_snapshot!$AT$2 -> Reference: 2025 | J8: ="Reference: "&src_city_snapshot!$AV$2 -> Reference: 2025
A10: ="Housing completions — H1 "&src_city_snapshot!$AW$2&" vs H1 "&(src_city_snapshot!$AW$2-1) -> Housing completions — H1 2026 vs H1 2025
A29: ="Key takeaways — H1 "&src_city_snapshot!$AW$2&" supply update" -> Key takeaways — H1 2026 supply update
A30: ="Median change across 17 cities: "&TEXT(MEDIAN('City Comparison'!$J$8:$J$24),"0.0%")&"." -> Median change across 17 cities: -8,6%.
A31: {="Largest increase in units: "&INDEX('City Comparison'!$A$8:$A$24,MATCH(MAX('City Comparison'!$K$8:$K$24),'City Comparison'!$K$8:$K$24,0))&": "&TEXT(MAX('City Comparison'!$K$8:$K$24),"+#,##0;-#,##0;0")&" dwellings ("&TEXT(INDEX('City Comparison'!$J$8:$J$24,MATCH(MAX('City Comparison'!$K$8:$K$24),'City Comparison'!$K$8:$K$24,0)),"0.0%")&")."} -> Largest increase in units: Kraków: +1 770 dwellings (64,8%).
A32: {="Largest decline in units: "&INDEX('City Comparison'!$A$8:$A$24,MATCH(MIN('City Comparison'!$K$8:$K$24),'City Comparison'!$K$8:$K$24,0))&": "&TEXT(MIN('City Comparison'!$K$8:$K$24),"+#,##0;-#,##0;0")&" dwellings ("&TEXT(INDEX('City Comparison'!$J$8:$J$24,MATCH(MIN('City Comparison'!$K$8:$K$24),'City Comparison'!$K$8:$K$24,0)),"0.0%")&")."} -> Largest decline in units: Warszawa: -1 433 dwellings (-17,3%).
A33: {="Largest percentage increase: "&INDEX('City Comparison'!$A$8:$A$24,MATCH(MAX('City Comparison'!$J$8:$J$24),'City Comparison'!$J$8:$J$24,0))&": "&TEXT(MAX('City Comparison'!$J$8:$J$24),"0.0%")&" ("&TEXT(INDEX('City Comparison'!$H$8:$H$24,MATCH(MAX('City Comparison'!$J$8:$J$24),'City Comparison'!$J$8:$J$24,0)),"#,##0")&" → "&TEXT(INDEX('City Comparison'!$I$8:$I$24,MATCH(MAX('City Comparison'!$J$8:$J$24),'City Comparison'!$J$8:$J$24,0)),"#,##0")&")."} -> Largest percentage increase: Olsztyn: 299,0% (195 → 778).
A35: ="Interpretation note: H1 "&src_city_snapshot!$AW$2&" is a partial-year period and is compared only with H1 "&(src_city_snapshot!$AW$2-1)&". KPI cards intentionally use different reference periods; see Methodology." -> Interpretation note: H1 2026 is a partial-year period and is compared only with H1 2025. KPI cards intentionally use different reference periods; see Methodology.
A37: Source: NBP BaRN, GUS BDL | Reporting tables prepared in Python | Definitions and periods: Methodology

Sheet City Comparison
A1: City Comparison
A3: 17 cities compared on individual metrics. No composite score.
A4: Use the header filters to sort or narrow the table. Red shading = relatively less buyer-favorable within that metric white = relatively more favorable. No overall city score.
A7: City | B7: Secondary Price PLN/m² | C7: Primary Price PLN/m² | D7: Primary Premium % | E7: Affordability m² / salary | F7: Price Growth latest 4 YoY avg % | G7: Supply 2025 completed / 1k | H7: H1 2025 completed | I7: H1 2026 completed | J7: H1 Supply Change % | K7: H1 Change units
A8: {=INDEX(src_dim_city!$B$2:$B$18,MATCH(helper_report!$A16,src_dim_city!$A$2:$A$18,0))} -> Warszawa | B8: {=INDEX(src_city_snapshot!$D$2:$D$18,MATCH(helper_report!$A16,src_city_snapshot!$A$2:$A$18,0))} -> 16722.657 | C8: {=INDEX(src_city_snapshot!$C$2:$C$18,MATCH(helper_report!$A16,src_city_snapshot!$A$2:$A$18,0))} -> 16783.491 | D8: {=INDEX(src_city_snapshot!$K$2:$K$18,MATCH(helper_report!$A16,src_city_snapshot!$A$2:$A$18,0))} -> 0.36378587 | E8: {=INDEX(src_city_snapshot!$U$2:$U$18,MATCH(helper_report!$A16,src_city_snapshot!$A$2:$A$18,0))} -> 0.70416855 | F8: {=INDEX(src_city_snapshot!$I$2:$I$18,MATCH(helper_report!$A16,src_city_snapshot!$A$2:$A$18,0))} -> -0.82738646 | G8: {=INDEX(src_city_snapshot!$AK$2:$AK$18,MATCH(helper_report!$A16,src_city_snapshot!$A$2:$A$18,0))} -> 10.645723 | H8: =SUMIFS(src_fact_city_year!$AI$2:$AI$375,src_fact_city_year!$A$2:$A$375,helper_report!$A16,src_fact_city_year!$B$2:$B$375,src_city_snapshot!$AW$2-1) -> 8300 | I8: =SUMIFS(src_fact_city_year!$AI$2:$AI$375,src_fact_city_year!$A$2:$A$375,helper_report!$A16,src_fact_city_year!$B$2:$B$375,src_city_snapshot!$AW$2) -> 6867 | J8: =IFERROR(I8/H8-1,"") -> -0.1726506 | K8: =IF(OR(H8="",I8=""),"",I8-H8) -> -1433
A9: {=INDEX(src_dim_city!$B$2:$B$18,MATCH(helper_report!$A8,src_dim_city!$A$2:$A$18,0))} -> Kraków | B9: {=INDEX(src_city_snapshot!$D$2:$D$18,MATCH(helper_report!$A8,src_city_snapshot!$A$2:$A$18,0))} -> 14791.951 | C9: {=INDEX(src_city_snapshot!$C$2:$C$18,MATCH(helper_report!$A8,src_city_snapshot!$A$2:$A$18,0))} -> 15922.877 | D9: {=INDEX(src_city_snapshot!$K$2:$K$18,MATCH(helper_report!$A8,src_city_snapshot!$A$2:$A$18,0))} -> 7.6455528 | E9: {=INDEX(src_city_snapshot!$U$2:$U$18,MATCH(helper_report!$A8,src_city_snapshot!$A$2:$A$18,0))} -> 0.76133116 | F9: {=INDEX(src_city_snapshot!$I$2:$I$18,MATCH(helper_report!$A8,src_city_snapshot!$A$2:$A$18,0))} -> -1.084829 | G9: {=INDEX(src_city_snapshot!$AK$2:$AK$18,MATCH(helper_report!$A8,src_city_snapshot!$A$2:$A$18,0))} -> 9.8027363 | H9: =SUMIFS(src_fact_city_year!$AI$2:$AI$375,src_fact_city_year!$A$2:$A$375,helper_report!$A8,src_fact_city_year!$B$2:$B$375,src_city_snapshot!$AW$2-1) -> 2731 | I9: =SUMIFS(src_fact_city_year!$AI$2:$AI$375,src_fact_city_year!$A$2:$A$375,helper_report!$A8,src_fact_city_year!$B$2:$B$375,src_city_snapshot!$AW$2) -> 4501 | J9: =IFERROR(I9/H9-1,"") -> 0.64811424 | K9: =IF(OR(H9="",I9=""),"",I9-H9) -> 1770
A10: {=INDEX(src_dim_city!$B$2:$B$18,MATCH(helper_report!$A4,src_dim_city!$A$2:$A$18,0))} -> Gdańsk | B10: {=INDEX(src_city_snapshot!$D$2:$D$18,MATCH(helper_report!$A4,src_city_snapshot!$A$2:$A$18,0))} -> 14034.642 | C10: {=INDEX(src_city_snapshot!$C$2:$C$18,MATCH(helper_report!$A4,src_city_snapshot!$A$2:$A$18,0))} -> 14490.615 | D10: {=INDEX(src_city_snapshot!$K$2:$K$18,MATCH(helper_report!$A4,src_city_snapshot!$A$2:$A$18,0))} -> 3.248908 | E10: {=INDEX(src_city_snapshot!$U$2:$U$18,MATCH(helper_report!$A4,src_city_snapshot!$A$2:$A$18,0))} -> 0.82103419 | F10: {=INDEX(src_city_snapshot!$I$2:$I$18,MATCH(helper_report!$A4,src_city_snapshot!$A$2:$A$18,0))} -> 4.4716399 | G10: {=INDEX(src_city_snapshot!$AK$2:$AK$18,MATCH(helper_report!$A4,src_city_snapshot!$A$2:$A$18,0))} -> 11.754845 | H10: =SUMIFS(src_fact_city_year!$AI$2:$AI$375,src_fact_city_year!$A$2:$A$375,helper_report!$A4,src_fact_city_year!$B$2:$B$375,src_city_snapshot!$AW$2-1) -> 2194 | I10: =SUMIFS(src_fact_city_year!$AI$2:$AI$375,src_fact_city_year!$A$2:$A$375,helper_report!$A4,src_fact_city_year!$B$2:$B$375,src_city_snapshot!$AW$2) -> 1618 | J10: =IFERROR(I10/H10-1,"") -> -0.26253418 | K10: =IF(OR(H10="",I10=""),"",I10-H10) -> -576
A11: {=INDEX(src_dim_city!$B$2:$B$18,MATCH(helper_report!$A17,src_dim_city!$A$2:$A$18,0))} -> Wrocław | B11: {=INDEX(src_city_snapshot!$D$2:$D$18,MATCH(helper_report!$A17,src_city_snapshot!$A$2:$A$18,0))} -> 12589.783 | C11: {=INDEX(src_city_snapshot!$C$2:$C$18,MATCH(helper_report!$A17,src_city_snapshot!$A$2:$A$18,0))} -> 14312.254 | D11: {=INDEX(src_city_snapshot!$K$2:$K$18,MATCH(helper_report!$A17,src_city_snapshot!$A$2:$A$18,0))} -> 13.681501 | E11: {=INDEX(src_city_snapshot!$U$2:$U$18,MATCH(helper_report!$A17,src_city_snapshot!$A$2:$A$18,0))} -> 0.80601293 | F11: {=INDEX(src_city_snapshot!$I$2:$I$18,MATCH(helper_report!$A17,src_city_snapshot!$A$2:$A$18,0))} -> -1.3611285 | G11: {=INDEX(src_city_snapshot!$AK$2:$AK$18,MATCH(helper_report!$A17,src_city_snapshot!$A$2:$A$18,0))} -> 11.449048 | H11: =SUMIFS(src_fact_city_year!$AI$2:$AI$375,src_fact_city_year!$A$2:$A$375,helper_report!$A17,src_fact_city_year!$B$2:$B$375,src_city_snapshot!$AW$2-1) -> 3481 | I11: =SUMIFS(src_fact_city_year!$AI$2:$AI$375,src_fact_city_year!$A$2:$A$375,helper_report!$A17,src_fact_city_year!$B$2:$B$375,src_city_snapshot!$AW$2) -> 3182 | J11: =IFERROR(I11/H11-1,"") -> -0.085894858 | K11: =IF(OR(H11="",I11=""),"",I11-H11) -> -299
A12: {=INDEX(src_dim_city!$B$2:$B$18,MATCH(helper_report!$A5,src_dim_city!$A$2:$A$18,0))} -> Gdynia | B12: {=INDEX(src_city_snapshot!$D$2:$D$18,MATCH(helper_report!$A5,src_city_snapshot!$A$2:$A$18,0))} -> 12266.795 | C12: {=INDEX(src_city_snapshot!$C$2:$C$18,MATCH(helper_report!$A5,src_city_snapshot!$A$2:$A$18,0))} -> 12886.982 | D12: {=INDEX(src_city_snapshot!$K$2:$K$18,MATCH(helper_report!$A5,src_city_snapshot!$A$2:$A$18,0))} -> 5.0558178 | E12: {=INDEX(src_city_snapshot!$U$2:$U$18,MATCH(helper_report!$A5,src_city_snapshot!$A$2:$A$18,0))} -> 0.83120516 | F12: {=INDEX(src_city_snapshot!$I$2:$I$18,MATCH(helper_report!$A5,src_city_snapshot!$A$2:$A$18,0))} -> 1.4936952 | G12: {=INDEX(src_city_snapshot!$AK$2:$AK$18,MATCH(helper_report!$A5,src_city_snapshot!$A$2:$A$18,0))} -> 3.6101536 | H12: =SUMIFS(src_fact_city_year!$AI$2:$AI$375,src_fact_city_year!$A$2:$A$375,helper_report!$A5,src_fact_city_year!$B$2:$B$375,src_city_snapshot!$AW$2-1) -> 296 | I12: =SUMIFS(src_fact_city_year!$AI$2:$AI$375,src_fact_city_year!$A$2:$A$375,helper_report!$A5,src_fact_city_year!$B$2:$B$375,src_city_snapshot!$AW$2) -> 247 | J12: =IFERROR(I12/H12-1,"") -> -0.16554054 | K12: =IF(OR(H12="",I12=""),"",I12-H12) -> -49
A13: {=INDEX(src_dim_city!$B$2:$B$18,MATCH(helper_report!$A14,src_dim_city!$A$2:$A$18,0))} -> Rzeszów | B13: {=INDEX(src_city_snapshot!$D$2:$D$18,MATCH(helper_report!$A14,src_city_snapshot!$A$2:$A$18,0))} -> 10973.994 | C13: {=INDEX(src_city_snapshot!$C$2:$C$18,MATCH(helper_report!$A14,src_city_snapshot!$A$2:$A$18,0))} -> 10329.021 | D13: {=INDEX(src_city_snapshot!$K$2:$K$18,MATCH(helper_report!$A14,src_city_snapshot!$A$2:$A$18,0))} -> -5.8772826 | E13: {=INDEX(src_city_snapshot!$U$2:$U$18,MATCH(helper_report!$A14,src_city_snapshot!$A$2:$A$18,0))} -> 0.89436017 | F13: {=INDEX(src_city_snapshot!$I$2:$I$18,MATCH(helper_report!$A14,src_city_snapshot!$A$2:$A$18,0))} -> 1.9723635 | G13: {=INDEX(src_city_snapshot!$AK$2:$AK$18,MATCH(helper_report!$A14,src_city_snapshot!$A$2:$A$18,0))} -> 15.598872 | H13: =SUMIFS(src_fact_city_year!$AI$2:$AI$375,src_fact_city_year!$A$2:$A$375,helper_report!$A14,src_fact_city_year!$B$2:$B$375,src_city_snapshot!$AW$2-1) -> 1714 | I13: =SUMIFS(src_fact_city_year!$AI$2:$AI$375,src_fact_city_year!$A$2:$A$375,helper_report!$A14,src_fact_city_year!$B$2:$B$375,src_city_snapshot!$AW$2) -> 1526 | J13: =IFERROR(I13/H13-1,"") -> -0.10968495 | K13: =IF(OR(H13="",I13=""),"",I13-H13) -> -188
A14: {=INDEX(src_dim_city!$B$2:$B$18,MATCH(helper_report!$A13,src_dim_city!$A$2:$A$18,0))} -> Poznań | B14: {=INDEX(src_city_snapshot!$D$2:$D$18,MATCH(helper_report!$A13,src_city_snapshot!$A$2:$A$18,0))} -> 10890.792 | C14: {=INDEX(src_city_snapshot!$C$2:$C$18,MATCH(helper_report!$A13,src_city_snapshot!$A$2:$A$18,0))} -> 12765.859 | D14: {=INDEX(src_city_snapshot!$K$2:$K$18,MATCH(helper_report!$A13,src_city_snapshot!$A$2:$A$18,0))} -> 17.216996 | E14: {=INDEX(src_city_snapshot!$U$2:$U$18,MATCH(helper_report!$A13,src_city_snapshot!$A$2:$A$18,0))} -> 0.94172939 | F14: {=INDEX(src_city_snapshot!$I$2:$I$18,MATCH(helper_report!$A13,src_city_snapshot!$A$2:$A$18,0))} -> 1.6999744 | G14: {=INDEX(src_city_snapshot!$AK$2:$AK$18,MATCH(helper_report!$A13,src_city_snapshot!$A$2:$A$18,0))} -> 10.483948 | H14: =SUMIFS(src_fact_city_year!$AI$2:$AI$375,src_fact_city_year!$A$2:$A$375,helper_report!$A13,src_fact_city_year!$B$2:$B$375,src_city_snapshot!$AW$2-1) -> 1791 | I14: =SUMIFS(src_fact_city_year!$AI$2:$AI$375,src_fact_city_year!$A$2:$A$375,helper_report!$A13,src_fact_city_year!$B$2:$B$375,src_city_snapshot!$AW$2) -> 2319 | J14: =IFERROR(I14/H14-1,"") -> 0.29480737 | K14: =IF(OR(H14="",I14=""),"",I14-H14) -> 528
A15: {=INDEX(src_dim_city!$B$2:$B$18,MATCH(helper_report!$A9,src_dim_city!$A$2:$A$18,0))} -> Lublin | B15: {=INDEX(src_city_snapshot!$D$2:$D$18,MATCH(helper_report!$A9,src_city_snapshot!$A$2:$A$18,0))} -> 10219.03 | C15: {=INDEX(src_city_snapshot!$C$2:$C$18,MATCH(helper_report!$A9,src_city_snapshot!$A$2:$A$18,0))} -> 10889.14 | D15: {=INDEX(src_city_snapshot!$K$2:$K$18,MATCH(helper_report!$A9,src_city_snapshot!$A$2:$A$18,0))} -> 6.5574717 | E15: {=INDEX(src_city_snapshot!$U$2:$U$18,MATCH(helper_report!$A9,src_city_snapshot!$A$2:$A$18,0))} -> 0.92680109 | F15: {=INDEX(src_city_snapshot!$I$2:$I$18,MATCH(helper_report!$A9,src_city_snapshot!$A$2:$A$18,0))} -> 1.9584294 | G15: {=INDEX(src_city_snapshot!$AK$2:$AK$18,MATCH(helper_report!$A9,src_city_snapshot!$A$2:$A$18,0))} -> 8.879481 | H15: =SUMIFS(src_fact_city_year!$AI$2:$AI$375,src_fact_city_year!$A$2:$A$375,helper_report!$A9,src_fact_city_year!$B$2:$B$375,src_city_snapshot!$AW$2-1) -> 934 | I15: =SUMIFS(src_fact_city_year!$AI$2:$AI$375,src_fact_city_year!$A$2:$A$375,helper_report!$A9,src_fact_city_year!$B$2:$B$375,src_city_snapshot!$AW$2) -> 1433 | J15: =IFERROR(I15/H15-1,"") -> 0.53426124 | K15: =IF(OR(H15="",I15=""),"",I15-H15) -> 499
A16: {=INDEX(src_dim_city!$B$2:$B$18,MATCH(helper_report!$A2,src_dim_city!$A$2:$A$18,0))} -> Białystok | B16: {=INDEX(src_city_snapshot!$D$2:$D$18,MATCH(helper_report!$A2,src_city_snapshot!$A$2:$A$18,0))} -> 9403.1318 | C16: {=INDEX(src_city_snapshot!$C$2:$C$18,MATCH(helper_report!$A2,src_city_snapshot!$A$2:$A$18,0))} -> 10926.219 | D16: {=INDEX(src_city_snapshot!$K$2:$K$18,MATCH(helper_report!$A2,src_city_snapshot!$A$2:$A$18,0))} -> 16.197656 | E16: {=INDEX(src_city_snapshot!$U$2:$U$18,MATCH(helper_report!$A2,src_city_snapshot!$A$2:$A$18,0))} -> 0.95897791 | F16: {=INDEX(src_city_snapshot!$I$2:$I$18,MATCH(helper_report!$A2,src_city_snapshot!$A$2:$A$18,0))} -> 0.65780585 | G16: {=INDEX(src_city_snapshot!$AK$2:$AK$18,MATCH(helper_report!$A2,src_city_snapshot!$A$2:$A$18,0))} -> 5.8442791 | H16: =SUMIFS(src_fact_city_year!$AI$2:$AI$375,src_fact_city_year!$A$2:$A$375,helper_report!$A2,src_fact_city_year!$B$2:$B$375,src_city_snapshot!$AW$2-1) -> 1120 | I16: =SUMIFS(src_fact_city_year!$AI$2:$AI$375,src_fact_city_year!$A$2:$A$375,helper_report!$A2,src_fact_city_year!$B$2:$B$375,src_city_snapshot!$AW$2) -> 311 | J16: =IFERROR(I16/H16-1,"") -> -0.72232143 | K16: =IF(OR(H16="",I16=""),"",I16-H16) -> -809
A17: {=INDEX(src_dim_city!$B$2:$B$18,MATCH(helper_report!$A15,src_dim_city!$A$2:$A$18,0))} -> Szczecin | B17: {=INDEX(src_city_snapshot!$D$2:$D$18,MATCH(helper_report!$A15,src_city_snapshot!$A$2:$A$18,0))} -> 9363.2163 | C17: {=INDEX(src_city_snapshot!$C$2:$C$18,MATCH(helper_report!$A15,src_city_snapshot!$A$2:$A$18,0))} -> 11427.47 | D17: {=INDEX(src_city_snapshot!$K$2:$K$18,MATCH(helper_report!$A15,src_city_snapshot!$A$2:$A$18,0))} -> 22.046419 | E17: {=INDEX(src_city_snapshot!$U$2:$U$18,MATCH(helper_report!$A15,src_city_snapshot!$A$2:$A$18,0))} -> 1.069479 | F17: {=INDEX(src_city_snapshot!$I$2:$I$18,MATCH(helper_report!$A15,src_city_snapshot!$A$2:$A$18,0))} -> 1.4283439 | G17: {=INDEX(src_city_snapshot!$AK$2:$AK$18,MATCH(helper_report!$A15,src_city_snapshot!$A$2:$A$18,0))} -> 6.1792823 | H17: =SUMIFS(src_fact_city_year!$AI$2:$AI$375,src_fact_city_year!$A$2:$A$375,helper_report!$A15,src_fact_city_year!$B$2:$B$375,src_city_snapshot!$AW$2-1) -> 961 | I17: =SUMIFS(src_fact_city_year!$AI$2:$AI$375,src_fact_city_year!$A$2:$A$375,helper_report!$A15,src_fact_city_year!$B$2:$B$375,src_city_snapshot!$AW$2) -> 680 | J17: =IFERROR(I17/H17-1,"") -> -0.29240375 | K17: =IF(OR(H17="",I17=""),"",I17-H17) -> -281
A18: {=INDEX(src_dim_city!$B$2:$B$18,MATCH(helper_report!$A12,src_dim_city!$A$2:$A$18,0))} -> Opole | B18: {=INDEX(src_city_snapshot!$D$2:$D$18,MATCH(helper_report!$A12,src_city_snapshot!$A$2:$A$18,0))} -> 9215.2766 | C18: {=INDEX(src_city_snapshot!$C$2:$C$18,MATCH(helper_report!$A12,src_city_snapshot!$A$2:$A$18,0))} -> 11624.601 | D18: {=INDEX(src_city_snapshot!$K$2:$K$18,MATCH(helper_report!$A12,src_city_snapshot!$A$2:$A$18,0))} -> 26.144899 | E18: {=INDEX(src_city_snapshot!$U$2:$U$18,MATCH(helper_report!$A12,src_city_snapshot!$A$2:$A$18,0))} -> 1.0657993 | F18: {=INDEX(src_city_snapshot!$I$2:$I$18,MATCH(helper_report!$A12,src_city_snapshot!$A$2:$A$18,0))} -> 3.8899978 | G18: {=INDEX(src_city_snapshot!$AK$2:$AK$18,MATCH(helper_report!$A12,src_city_snapshot!$A$2:$A$18,0))} -> 2.9177825 | H18: =SUMIFS(src_fact_city_year!$AI$2:$AI$375,src_fact_city_year!$A$2:$A$375,helper_report!$A12,src_fact_city_year!$B$2:$B$375,src_city_snapshot!$AW$2-1) -> 165 | I18: =SUMIFS(src_fact_city_year!$AI$2:$AI$375,src_fact_city_year!$A$2:$A$375,helper_report!$A12,src_fact_city_year!$B$2:$B$375,src_city_snapshot!$AW$2) -> 323 | J18: =IFERROR(I18/H18-1,"") -> 0.95757576 | K18: =IF(OR(H18="",I18=""),"",I18-H18) -> 158
A19: {=INDEX(src_dim_city!$B$2:$B$18,MATCH(helper_report!$A11,src_dim_city!$A$2:$A$18,0))} -> Olsztyn | B19: {=INDEX(src_city_snapshot!$D$2:$D$18,MATCH(helper_report!$A11,src_city_snapshot!$A$2:$A$18,0))} -> 8940.509 | C19: {=INDEX(src_city_snapshot!$C$2:$C$18,MATCH(helper_report!$A11,src_city_snapshot!$A$2:$A$18,0))} -> 10680.51 | D19: {=INDEX(src_city_snapshot!$K$2:$K$18,MATCH(helper_report!$A11,src_city_snapshot!$A$2:$A$18,0))} -> 19.46199 | E19: {=INDEX(src_city_snapshot!$U$2:$U$18,MATCH(helper_report!$A11,src_city_snapshot!$A$2:$A$18,0))} -> 1.0801307 | F19: {=INDEX(src_city_snapshot!$I$2:$I$18,MATCH(helper_report!$A11,src_city_snapshot!$A$2:$A$18,0))} -> 3.8693641 | G19: {=INDEX(src_city_snapshot!$AK$2:$AK$18,MATCH(helper_report!$A11,src_city_snapshot!$A$2:$A$18,0))} -> 3.6176178 | H19: =SUMIFS(src_fact_city_year!$AI$2:$AI$375,src_fact_city_year!$A$2:$A$375,helper_report!$A11,src_fact_city_year!$B$2:$B$375,src_city_snapshot!$AW$2-1) -> 195 | I19: =SUMIFS(src_fact_city_year!$AI$2:$AI$375,src_fact_city_year!$A$2:$A$375,helper_report!$A11,src_fact_city_year!$B$2:$B$375,src_city_snapshot!$AW$2) -> 778 | J19: =IFERROR(I19/H19-1,"") -> 2.9897436 | K19: =IF(OR(H19="",I19=""),"",I19-H19) -> 583
A20: {=INDEX(src_dim_city!$B$2:$B$18,MATCH(helper_report!$A18,src_dim_city!$A$2:$A$18,0))} -> Zielona Góra | B20: {=INDEX(src_city_snapshot!$D$2:$D$18,MATCH(helper_report!$A18,src_city_snapshot!$A$2:$A$18,0))} -> 8633.384 | C20: {=INDEX(src_city_snapshot!$C$2:$C$18,MATCH(helper_report!$A18,src_city_snapshot!$A$2:$A$18,0))} -> 9457.8511 | D20: {=INDEX(src_city_snapshot!$K$2:$K$18,MATCH(helper_report!$A18,src_city_snapshot!$A$2:$A$18,0))} -> 9.549755 | E20: {=INDEX(src_city_snapshot!$U$2:$U$18,MATCH(helper_report!$A18,src_city_snapshot!$A$2:$A$18,0))} -> 1.1143175 | F20: {=INDEX(src_city_snapshot!$I$2:$I$18,MATCH(helper_report!$A18,src_city_snapshot!$A$2:$A$18,0))} -> 7.7493366 | G20: {=INDEX(src_city_snapshot!$AK$2:$AK$18,MATCH(helper_report!$A18,src_city_snapshot!$A$2:$A$18,0))} -> 7.6607091 | H20: =SUMIFS(src_fact_city_year!$AI$2:$AI$375,src_fact_city_year!$A$2:$A$375,helper_report!$A18,src_fact_city_year!$B$2:$B$375,src_city_snapshot!$AW$2-1) -> 397 | I20: =SUMIFS(src_fact_city_year!$AI$2:$AI$375,src_fact_city_year!$A$2:$A$375,helper_report!$A18,src_fact_city_year!$B$2:$B$375,src_city_snapshot!$AW$2) -> 296 | J20: =IFERROR(I20/H20-1,"") -> -0.25440806 | K20: =IF(OR(H20="",I20=""),"",I20-H20) -> -101
A21: {=INDEX(src_dim_city!$B$2:$B$18,MATCH(helper_report!$A3,src_dim_city!$A$2:$A$18,0))} -> Bydgoszcz | B21: {=INDEX(src_city_snapshot!$D$2:$D$18,MATCH(helper_report!$A3,src_city_snapshot!$A$2:$A$18,0))} -> 8341.8674 | C21: {=INDEX(src_city_snapshot!$C$2:$C$18,MATCH(helper_report!$A3,src_city_snapshot!$A$2:$A$18,0))} -> 10774.886 | D21: {=INDEX(src_city_snapshot!$K$2:$K$18,MATCH(helper_report!$A3,src_city_snapshot!$A$2:$A$18,0))} -> 29.166357 | E21: {=INDEX(src_city_snapshot!$U$2:$U$18,MATCH(helper_report!$A3,src_city_snapshot!$A$2:$A$18,0))} -> 1.1845936 | F21: {=INDEX(src_city_snapshot!$I$2:$I$18,MATCH(helper_report!$A3,src_city_snapshot!$A$2:$A$18,0))} -> 1.864496 | G21: {=INDEX(src_city_snapshot!$AK$2:$AK$18,MATCH(helper_report!$A3,src_city_snapshot!$A$2:$A$18,0))} -> 3.653121 | H21: =SUMIFS(src_fact_city_year!$AI$2:$AI$375,src_fact_city_year!$A$2:$A$375,helper_report!$A3,src_fact_city_year!$B$2:$B$375,src_city_snapshot!$AW$2-1) -> 345 | I21: =SUMIFS(src_fact_city_year!$AI$2:$AI$375,src_fact_city_year!$A$2:$A$375,helper_report!$A3,src_fact_city_year!$B$2:$B$375,src_city_snapshot!$AW$2) -> 985 | J21: =IFERROR(I21/H21-1,"") -> 1.8550725 | K21: =IF(OR(H21="",I21=""),"",I21-H21) -> 640
A22: {=INDEX(src_dim_city!$B$2:$B$18,MATCH(helper_report!$A7,src_dim_city!$A$2:$A$18,0))} -> Kielce | B22: {=INDEX(src_city_snapshot!$D$2:$D$18,MATCH(helper_report!$A7,src_city_snapshot!$A$2:$A$18,0))} -> 8192.6461 | C22: {=INDEX(src_city_snapshot!$C$2:$C$18,MATCH(helper_report!$A7,src_city_snapshot!$A$2:$A$18,0))} -> 10401.899 | D22: {=INDEX(src_city_snapshot!$K$2:$K$18,MATCH(helper_report!$A7,src_city_snapshot!$A$2:$A$18,0))} -> 26.966291 | E22: {=INDEX(src_city_snapshot!$U$2:$U$18,MATCH(helper_report!$A7,src_city_snapshot!$A$2:$A$18,0))} -> 1.1105757 | F22: {=INDEX(src_city_snapshot!$I$2:$I$18,MATCH(helper_report!$A7,src_city_snapshot!$A$2:$A$18,0))} -> 1.4904394 | G22: {=INDEX(src_city_snapshot!$AK$2:$AK$18,MATCH(helper_report!$A7,src_city_snapshot!$A$2:$A$18,0))} -> 5.8154418 | H22: =SUMIFS(src_fact_city_year!$AI$2:$AI$375,src_fact_city_year!$A$2:$A$375,helper_report!$A7,src_fact_city_year!$B$2:$B$375,src_city_snapshot!$AW$2-1) -> 587 | I22: =SUMIFS(src_fact_city_year!$AI$2:$AI$375,src_fact_city_year!$A$2:$A$375,helper_report!$A7,src_fact_city_year!$B$2:$B$375,src_city_snapshot!$AW$2) -> 493 | J22: =IFERROR(I22/H22-1,"") -> -0.16013629 | K22: =IF(OR(H22="",I22=""),"",I22-H22) -> -94
A23: {=INDEX(src_dim_city!$B$2:$B$18,MATCH(helper_report!$A6,src_dim_city!$A$2:$A$18,0))} -> Katowice | B23: {=INDEX(src_city_snapshot!$D$2:$D$18,MATCH(helper_report!$A6,src_city_snapshot!$A$2:$A$18,0))} -> 8101.6961 | C23: {=INDEX(src_city_snapshot!$C$2:$C$18,MATCH(helper_report!$A6,src_city_snapshot!$A$2:$A$18,0))} -> 11840.15 | D23: {=INDEX(src_city_snapshot!$K$2:$K$18,MATCH(helper_report!$A6,src_city_snapshot!$A$2:$A$18,0))} -> 46.144085 | E23: {=INDEX(src_city_snapshot!$U$2:$U$18,MATCH(helper_report!$A6,src_city_snapshot!$A$2:$A$18,0))} -> 1.3236617 | F23: {=INDEX(src_city_snapshot!$I$2:$I$18,MATCH(helper_report!$A6,src_city_snapshot!$A$2:$A$18,0))} -> 1.4105917 | G23: {=INDEX(src_city_snapshot!$AK$2:$AK$18,MATCH(helper_report!$A6,src_city_snapshot!$A$2:$A$18,0))} -> 8.3991882 | H23: =SUMIFS(src_fact_city_year!$AI$2:$AI$375,src_fact_city_year!$A$2:$A$375,helper_report!$A6,src_fact_city_year!$B$2:$B$375,src_city_snapshot!$AW$2-1) -> 1269 | I23: =SUMIFS(src_fact_city_year!$AI$2:$AI$375,src_fact_city_year!$A$2:$A$375,helper_report!$A6,src_fact_city_year!$B$2:$B$375,src_city_snapshot!$AW$2) -> 1420 | J23: =IFERROR(I23/H23-1,"") -> 0.11899133 | K23: =IF(OR(H23="",I23=""),"",I23-H23) -> 151
A24: {=INDEX(src_dim_city!$B$2:$B$18,MATCH(helper_report!$A10,src_dim_city!$A$2:$A$18,0))} -> Łódź | B24: {=INDEX(src_city_snapshot!$D$2:$D$18,MATCH(helper_report!$A10,src_city_snapshot!$A$2:$A$18,0))} -> 8019.663 | C24: {=INDEX(src_city_snapshot!$C$2:$C$18,MATCH(helper_report!$A10,src_city_snapshot!$A$2:$A$18,0))} -> 9945.4872 | D24: {=INDEX(src_city_snapshot!$K$2:$K$18,MATCH(helper_report!$A10,src_city_snapshot!$A$2:$A$18,0))} -> 24.01378 | E24: {=INDEX(src_city_snapshot!$U$2:$U$18,MATCH(helper_report!$A10,src_city_snapshot!$A$2:$A$18,0))} -> 1.1555262 | F24: {=INDEX(src_city_snapshot!$I$2:$I$18,MATCH(helper_report!$A10,src_city_snapshot!$A$2:$A$18,0))} -> 0.72083012 | G24: {=INDEX(src_city_snapshot!$AK$2:$AK$18,MATCH(helper_report!$A10,src_city_snapshot!$A$2:$A$18,0))} -> 9.0135234 | H24: =SUMIFS(src_fact_city_year!$AI$2:$AI$375,src_fact_city_year!$A$2:$A$375,helper_report!$A10,src_fact_city_year!$B$2:$B$375,src_city_snapshot!$AW$2-1) -> 2263 | I24: =SUMIFS(src_fact_city_year!$AI$2:$AI$375,src_fact_city_year!$A$2:$A$375,helper_report!$A10,src_fact_city_year!$B$2:$B$375,src_city_snapshot!$AW$2) -> 2602 | J24: =IFERROR(I24/H24-1,"") -> 0.14980115 | K24: =IF(OR(H24="",I24=""),"",I24-H24) -> 339

Sheet Methodology
A1: Methodology
A3: Definitions, reference periods, caveats and source-layer structure.
A5: 1. Metric Definitions
A6: Metric | B6: Definition | C6: Interpretation | E6: Metric | F6: Definition | G6: Interpretation
A7: Secondary Price | B7: Latest NBP secondary-market transaction price per m². | C7: Lower value = lower headline transaction price. | E7: ="H1 "&(src_city_snapshot!$AW$2-1)&" / H1 "&src_city_snapshot!$AW$2 -> H1 2025 / H1 2026 | F7: Completed dwellings from January through June. | G7: Raw counts for the current supply update.
A8: Primary Premium | B8: (Primary price / Secondary price) - 1, from the latest NBP period. | C8: Lower premium = smaller price gap between primary and secondary markets. | E8: H1 Supply Change | F8: ="H1 "&src_city_snapshot!$AW$2&" completed / H1 "&(src_city_snapshot!$AW$2-1)&" completed - 1." -> H1 2026 completed / H1 2025 completed - 1. | G8: Positive = more completions than in the same half-year a year earlier.
A9: Affordability | B9: Average monthly gross wage / annual secondary transaction price per m². | C9: Higher value = more m² equivalent to one average monthly gross wage.
A10: Price Growth | B10: Average of the latest 4 secondary-market YoY price changes. | C10: Recent price pressure; descriptive, not a forecast.
A11: Completed Supply / 1k | B11: ="Completed dwellings in "&src_city_snapshot!$AV$2&" / mid-year population × 1,000." -> Completed dwellings in 2025 / mid-year population × 1,000. | C11: Higher value = more completed dwellings relative to population.
A13: 2. Reference Periods
A14: Metric | B14: Reference period | C14: Why
A15: Secondary / Primary Price | B15: =src_city_snapshot!$AS$2 -> 2026Q2 | C15: Latest NBP price period in the frozen snapshot.
A16: Affordability | B16: =src_city_snapshot!$AT$2 -> 2025 | C16: Latest full year with wage + annual price data.
A17: Completed Supply / 1k | B17: =src_city_snapshot!$AV$2 -> 2025 | C17: Latest full-year supply; H1 2026 is not annualized.
A18: H1 Supply Change | B18: ="H1 "&src_city_snapshot!$AW$2&" vs H1 "&(src_city_snapshot!$AW$2-1) -> H1 2026 vs H1 2025 | C18: Like-for-like partial-year comparison.
A19: Price Growth | B19: ="Latest 4 NBP YoY periods through "&src_city_snapshot!$AS$2 -> Latest 4 NBP YoY periods through 2026Q2 | C19: Reduces dependence on a single YoY observation.
A21: 3. Caveats & Reporting Rules
A22: • Affordability is a proxy, not mortgage affordability or a full cost-of-living measure.
A23: ="• H1 "&src_city_snapshot!$AW$2&" is partial-year data and is compared only with H1 "&(src_city_snapshot!$AW$2-1)&"; it is not mechanically annualized." -> • H1 2026 is partial-year data and is compared only with H1 2025; it is not mechanically annualized.
A24: • Annual NBP prices require all 4 observations; incomplete years remain blank.
A25: • No composite city score is used; each comparison is based on one metric.
A26: • Different metrics intentionally use different reference periods because sources update at different frequencies.
A29: 4. Source Layer — hidden reporting CSV tabs
A30: Sheet | B30: Rows | C30: Purpose | E30: Workflow: Python cleaning / reporting exports → hidden src_* CSV tabs → spreadsheet formulas → report. The source tabs remain in the workbook for audit and lineage, but are hidden from the normal presentation view. helper_report is also hidden and exists only for display ordering and chart sorting.
A31: src_city_snapshot | B31: 17 | C31: Latest city-level reporting snapshot used by KPI and comparison metrics.
A32: src_dim_city | B32: 17 | C32: 17-city dimension and labels.
A33: src_dim_nbp_period | B33: 80 | C33: NBP period dimension.
A34: src_dim_year | B34: 22 | C34: Year dimension.
A35: src_fact_city_year | B35: 374 | C35: Annual city facts, including H1 supply fields.
A36: src_fact_hedonic_period | B36: 1200 | C36: Hedonic reporting fact retained for lineage/future extension.
A37: src_fact_price_period | B37: 1360 | C37: Period-level price fact retained for lineage/future extension.

Sheet src_city_snapshot
A1: city_id | B1: nbp_period_id | C1: primary_transaction_price_pln_m2 | D1: secondary_transaction_price_pln_m2 | E1: primary_transaction_yoy_pct | F1: primary_yoy_4p_avg_pct | G1: primary_momentum_change_pp | H1: secondary_transaction_yoy_pct | I1: secondary_yoy_4p_avg_pct | J1: secondary_momentum_change_pp | K1: primary_secondary_premium_pct | L1: primary_transaction_methodology_break | M1: primary_transaction_methodology_note | N1: primary_premium_historical_median_pct | O1: primary_premium_historical_min_pct | P1: primary_premium_historical_max_pct | Q1: avg_gross_monthly_wage_pln | R1: primary_annual_transaction_price_pln_m2 | S1: secondary_annual_transaction_price_pln_m2 | T1: primary_affordability_m2 | U1: secondary_affordability_m2 | V1: primary_affordability_yoy_pct | W1: secondary_affordability_yoy_pct | X1: primary_annual_price_yoy_pct | Y1: secondary_annual_price_yoy_pct | Z1: wage_yoy_pct | AA1: primary_affordability_2019_m2 | AB1: secondary_affordability_2019_m2 | AC1: sold_units | AD1: sold_units_per_1000 | AE1: transactions | AF1: transactions_per_1000 | AG1: avg_sold_area_m2 | AH1: started | AI1: started_per_1000 | AJ1: completed | AK1: completed_per_1000 | AL1: started_h1 | AM1: completed_h1 | AN1: started_h1_yoy_pct | AO1: completed_h1_yoy_pct | AP1: primary_premium_vs_historical_median_pp | AQ1: primary_affordability_change_since_2019_pct | AR1: secondary_affordability_change_since_2019_pct | AS1: price_reference_period | AT1: affordability_reference_year | AU1: market_activity_reference_year | AV1: supply_reference_year | AW1: supply_h1_reference_year | AX1: pareto_favorable_secondary | AY1: secondary_price_rank_lowest | AZ1: secondary_affordability_rank_highest | BA1: completed_supply_rank_highest | BB1: secondary_price_pressure_rank_lowest
A2: 1 | B2: 20262 | C2: 10926.219 | D2: 9403.1318 | E2: 4.485637 | F2: 1.9246065 | G2: -8.1815324 | H2: -0.1766421 | I2: 0.65780585 | J2: -13.318624 | K2: 16.197656 | L2: FALSE | N2: 13.395127 | O2: -1.5217602 | P2: 24.387882 | Q2: 9090.46 | R2: 10348.073 | S2: 9479.3216 | T2: 0.87846883 | U2: 0.95897791 | V2: 7.6195479 | W2: 2.577457 | X2: 1.9917958 | Y2: 7.0050992 | Z2: 9.7631096 | AA2: 0.85045897 | AB2: 0.91545854 | AC2: 4402 | AD2: 15.131984 | AE2: 4395 | AF2: 15.107921 | AG2: 49.156293 | AH2: 1891 | AI2: 6.5277802 | AJ2: 1693 | AK2: 5.8442791 | AL2: 1351 | AM2: 311 | AN2: 6.9675376 | AO2: -72.232143 | AP2: 2.8025289 | AQ2: 3.293499 | AR2: 4.7538328 | AS2: 2026Q2 | AT2: 2025 | AU2: 2024 | AV2: 2025 | AW2: 2026 | AX2: TRUE | AY2: 9 | AZ2: 9 | BA2: 12 | BB2: 4
A3: 2 | B3: 20262 | C3: 10774.886 | D3: 8341.8674 | E3: 10.450538 | F3: 13.545044 | G3: 6.4740335 | H3: 6.8922016 | I3: 1.864496 | J3: -3.2718332 | K3: 29.166357 | L3: FALSE | N3: 25.947045 | O3: -1.2833677 | P3: 41.9866 | Q3: 9219.1 | R3: 9950.4314 | S3: 7782.5 | T3: 0.92650254 | U3: 1.1845936 | V3: 0.21125594 | W3: 8.8021319 | X3: 8.8945869 | Y3: 0.29641085 | Z3: 9.1246332 | AA3: 0.81375246 | AB3: 1.007286 | AC3: 4328 | AD3: 13.317579 | AG3: 49.421858 | AH3: 1756 | AI3: 5.4455691 | AJ3: 1178 | AK3: 3.653121 | AL3: 539 | AM3: 985 | AN3: 21.396396 | AO3: 185.50725 | AP3: 3.2193112 | AQ3: 13.855575 | AR3: 17.602517 | AS3: 2026Q2 | AT3: 2025 | AU3: 2024 | AV3: 2025 | AW3: 2026 | AX3: FALSE | AY3: 4 | AZ3: 2 | BA3: 14 | BB3: 11
A4: 3 | B4: 20262 | C4: 14490.615 | D4: 14034.642 | E4: 2.897908 | F4: 7.6107044 | G4: -0.55098668 | H4: 4.6129284 | I4: 4.4716399 | J4: -5.9369519 | K4: 3.248908 | L4: FALSE | N4: 6.9606972 | O4: -5.1678116 | P4: 34.877085 | Q4: 10972.26 | R4: 14142.416 | S4: 13363.95 | T4: 0.77584054 | U4: 0.82103419 | V4: -1.3986052 | W4: 3.0119394 | X4: 10.097388 | Y4: 5.3834739 | Z4: 8.5575603 | AA4: 0.73114061 | AB4: 0.79462143 | AC4: 10037 | AD4: 20.574622 | AE4: 9985 | AF4: 20.468028 | AG4: 53.412374 | AH4: 5337 | AI4: 10.910541 | AJ4: 5750 | AK4: 11.754845 | AL4: 3109 | AM4: 1618 | AN4: -17.664195 | AO4: -26.253418 | AP4: -3.7117893 | AQ4: 6.1137253 | AR4: 3.3239428 | AS4: 2026Q2 | AT4: 2025 | AU4: 2024 | AV4: 2025 | AW4: 2026 | AX4: FALSE | AY4: 15 | AZ4: 14 | BA4: 2 | BB4: 16
A5: 4 | B5: 20262 | C5: 12886.982 | D5: 12266.795 | E5: -0.87120334 | F5: 3.173484 | G5: -5.8322325 | H5: 3.8913057 | I5: 1.4936952 | J5: -10.711979 | K5: 5.0558178 | L5: FALSE | N5: 16.721063 | O5: -1.0984939 | P5: 39.905509 | Q5: 9795.07 | R5: 13246.877 | S5: 11784.179 | T5: 0.73942486 | U5: 0.83120516 | V5: 4.7349712 | W5: 5.3520761 | X5: 3.9232901 | Y5: 3.3145545 | Z5: 8.844028 | AA5: 0.69183502 | AB5: 0.7973347 | AC5: 2676 | AD5: 11.124321 | AG5: 55.693199 | AH5: 1786 | AI5: 7.4626554 | AJ5: 864 | AK5: 3.6101536 | AL5: 1533 | AM5: 247 | AN5: 376.08696 | AO5: -16.554054 | AP5: -11.665246 | AQ5: 6.8787846 | AR5: 4.24796 | AS5: 2026Q2 | AT5: 2025 | AU5: 2024 | AV5: 2025 | AW5: 2026 | AX5: FALSE | AY5: 13 | AZ5: 13 | BA5: 16 | BB5: 9
A6: 5 | B6: 20262 | C6: 11840.15 | D6: 8101.6961 | E6: 0.83319736 | F6: 0.32336118 | G6: -12.632607 | H6: -0.64473768 | I6: 1.4105917 | J6: -8.1645658 | K6: 46.144085 | L6: FALSE | N6: 43.830588 | O6: 26.716879 | P6: 84.68385 | Q6: 10801.86 | R6: 11885.467 | S6: 8160.5898 | T6: 0.90882922 | U6: 1.3236617 | V6: 3.8864769 | W6: 2.6643376 | X6: 3.4443847 | Y6: 4.6758098 | Z6: 7.4647268 | AA6: 0.93432366 | AB6: 1.3302382 | AC6: 5565 | AD6: 20.011507 | AE6: 5710 | AF6: 20.532921 | AG6: 52.781366 | AH6: 3291 | AI6: 11.843071 | AJ6: 2334 | AK6: 8.3991882 | AL6: 1532 | AM6: 1420 | AN6: -34.107527 | AO6: 11.899133 | AP6: 2.3134978 | AQ6: -2.728651 | AR6: -0.49438851 | AS6: 2026Q2 | AT6: 2025 | AU6: 2024 | AV6: 2025 | AW6: 2026 | AX6: TRUE | AY6: 2 | AZ6: 1 | BA6: 9 | BB6: 6
A7: 6 | B7: 20262 | C7: 10401.899 | D7: 8192.6461 | E7: 7.6651442 | F7: 3.37887 | G7: -10.780715 | H7: 2.2291938 | I7: 1.4904394 | J7: -10.731231 | K7: 26.966291 | L7: FALSE | N7: 21.73071 | O7: -17.532161 | P7: 34.436147 | Q7: 9008.73 | R7: 9900.4246 | S7: 8111.7662 | T7: 0.9099337 | U7: 1.1105757 | V7: 4.6591188 | W7: 6.0502824 | X7: 4.8009234 | Y7: 3.4261489 | Z7: 9.683723 | AA7: 0.95042047 | AB7: 1.1634442 | AC7: 2227 | AD7: 12.289541 | AG7: 51.047149 | AH7: 1120 | AI7: 6.232818 | AJ7: 1045 | AK7: 5.8154418 | AL7: 785 | AM7: 493 | AN7: 56.374502 | AO7: -16.013629 | AP7: 5.2355805 | AQ7: -4.2598796 | AR7: -4.5441412 | AS7: 2026Q2 | AT7: 2025 | AU7: 2024 | AV7: 2025 | AW7: 2026 | AX7: FALSE | AY7: 3 | AZ7: 5 | BA7: 13 | BB7: 8
A8: 7 | B8: 20262 | C8: 15922.877 | D8: 14791.951 | E8: 1.4105937 | F8: -0.48398421 | G8: -14.051941 | H8: -1.1093816 | I8: -1.084829 | J8: -15.53447 | K8: 7.6455528 | L8: FALSE | N8: 4.8459127 | O8: -3.0124034 | P8: 38.304791 | Q8: 11419.23 | R8: 15644.821 | S8: 14999.031 | T8: 0.7299048 | U8: 0.76133116 | V8: 7.5442839 | W8: 7.0720905 | X8: 1.5563712 | Y8: 2.0042399 | Z8: 9.2180721 | AA8: 0.75391801 | AB8: 0.76449358 | AC8: 15120 | AD8: 18.72112 | AE8: 14770 | AF8: 18.28776 | AG8: 52.232196 | AH8: 7962 | AI8: 9.822475 | AJ8: 7946 | AK8: 9.8027363 | AL8: 3573 | AM8: 4501 | AN8: -33.992241 | AO8: 64.811424 | AP8: 2.7996401 | AQ8: -3.185122 | AR8: -0.41366186 | AS8: 2026Q2 | AT8: 2025 | AU8: 2024 | AV8: 2025 | AW8: 2026 | AX8: FALSE | AY8: 16 | AZ8: 16 | BA8: 6 | BB8: 2
A9: 8 | B9: 20262 | C9: 10889.14 | D9: 10219.03 | E9: -0.8114248 | F9: 0.043194192 | G9: -10.281055 | H9: 2.0496755 | I9: 1.9584294 | J9: -9.8947007 | K9: 6.5574717 | L9: FALSE | N9: 6.5194613 | O9: -11.50286 | P9: 18.921888 | Q9: 9288.09 | R9: 11002.312 | S9: 10021.665 | T9: 0.84419435 | U9: 0.92680109 | V9: 5.441238 | W9: 4.0925891 | X9: 3.5416263 | Y9: 4.8831367 | Z9: 9.1755726 | AA9: 0.8473803 | AB9: 0.90298413 | AC9: 5644 | AD9: 17.161901 | AG9: 50.998051 | AH9: 2155 | AI9: 6.5824842 | AJ9: 2907 | AK9: 8.879481 | AL9: 1433 | AM9: 1433 | AN9: 10.999225 | AO9: 53.426124 | AP9: 0.038010376 | AQ9: -0.37597719 | AR9: 2.6375828 | AS9: 2026Q2 | AT9: 2025 | AU9: 2024 | AV9: 2025 | AW9: 2026 | AX9: FALSE | AY9: 10 | AZ9: 11 | BA9: 8 | BB9: 12
A10: 9 | B10: 20262 | C10: 10680.51 | D10: 8940.509 | E10: 6.849218 | F10: 8.9043256 | G10: 0.27523846 | H10: 5.2766753 | I10: 3.8693641 | J10: -6.8059028 | K10: 19.46199 | L10: FALSE | N10: 12.030251 | O10: -29.798133 | P10: 28.917279 | Q10: 9304.52 | R10: 10043.432 | S10: 8614.2537 | T10: 0.92642829 | U10: 1.0801307 | V10: -1.3537493 | W10: 2.9348263 | X10: 9.5071065 | Y10: 4.9447098 | Z10: 8.0246548 | AA10: 0.86409653 | AB10: 0.98147459 | AC10: 2646 | AD10: 15.873111 | AE10: 2696 | AF10: 16.173057 | AG10: 51.587302 | AH10: 1092 | AI10: 6.5840644 | AJ10: 600 | AK10: 3.6176178 | AL10: 336 | AM10: 778 | AN10: -50.148368 | AO10: 298.97436 | AP10: 7.4317394 | AQ10: 7.2135181 | AR10: 10.051826 | AS10: 2026Q2 | AT10: 2025 | AU10: 2024 | AV10: 2025 | AW10: 2026 | AX10: FALSE | AY10: 6 | AZ10: 6 | BA10: 15 | BB10: 14
A11: 10 | B11: 20262 | C11: 11624.601 | D11: 9215.2766 | E11: 5.3213776 | F11: 3.7925396 | G11: -5.8793153 | H11: 5.3587302 | I11: 3.8899978 | J11: -8.3784712 | K11: 26.144899 | L11: FALSE | N11: 15.514617 | O11: -14.369936 | P11: 30.892219 | Q11: 9465.22 | R11: 11166.636 | S11: 8880.8649 | T11: 0.84763398 | U11: 1.0657993 | V11: 2.9300331 | W11: 4.9723577 | X11: 7.3762894 | Y11: 5.2871942 | Z11: 10.52245 | AA11: 0.94706608 | AB11: 1.0476436 | AC11: 1500 | AD11: 11.922551 | AE11: 1499 | AF11: 11.914603 | AG11: 53.374667 | AH11: 686 | AI11: 5.4838323 | AJ11: 365 | AK11: 2.9177825 | AL11: 277 | AM11: 323 | AN11: 53.888889 | AO11: 95.757576 | AP11: 10.630283 | AQ11: -10.498962 | AR11: 1.7330119 | AS11: 2026Q2 | AT11: 2025 | AU11: 2024 | AV11: 2025 | AW11: 2026 | AX11: FALSE | AY11: 7 | AZ11: 8 | BA11: 17 | BB11: 15
A12: 11 | B12: 20262 | C12: 12765.859 | D12: 10890.792 | E12: 2.4374453 | F12: 1.824535 | G12: -6.2103661 | H12: 0.094648207 | I12: 1.6999744 | J12: -9.1373288 | K12: 17.216996 | L12: FALSE | N12: 17.325584 | O12: -6.0297149 | P12: 50.975229 | Q12: 10294.78 | R12: 12441.147 | S12: 10931.782 | T12: 0.82747836 | U12: 0.94172939 | V12: 6.2773026 | W12: 3.8267553 | X12: 2.018369 | Y12: 4.4262343 | Z12: 8.4223708 | AA12: 0.79791403 | AB12: 0.90112246 | AC12: 9744 | AD12: 18.151403 | AE12: 9583 | AF12: 17.851488 | AG12: 52.883754 | AH12: 3130 | AI12: 5.8514188 | AJ12: 5608 | AK12: 10.483948 | AL12: 2515 | AM12: 2319 | AN12: 31.813417 | AO12: 29.480737 | AP12: -0.1085886 | AQ12: 3.705202 | AR12: 4.506262 | AS12: 2026Q2 | AT12: 2025 | AU12: 2024 | AV12: 2025 | AW12: 2026 | AX12: TRUE | AY12: 11 | AZ12: 10 | BA12: 5 | BB12: 10
A13: 12 | B13: 20262 | C13: 10329.021 | D13: 10973.994 | E13: -3.9940305 | F13: 1.3220909 | G13: -8.3929357 | H13: 2.364589 | I13: 1.9723635 | J13: -12.982477 | K13: -5.8772826 | L13: FALSE | N13: -0.09752964 | O13: -12.874421 | P13: 12.00577 | Q13: 9537.56 | R13: 10344.724 | S13: 10664.115 | T13: 0.92197341 | U13: 0.89436017 | V13: 4.4102323 | W13: 3.5384548 | X13: 5.2325223 | Y13: 6.1185635 | Z13: 9.873521 | AA13: 0.90949258 | AB13: 0.93423356 | AC13: 3574 | AD13: 18.077347 | AG13: 53.037633 | AH13: 1824 | AI13: 9.1870656 | AJ13: 3097 | AK13: 15.598872 | AL13: 1942 | AM13: 1526 | AN13: 75.905797 | AO13: -10.968495 | AP13: -5.779753 | AQ13: 1.3722847 | AR13: -4.268033 | AS13: 2026Q2 | AT13: 2025 | AU13: 2024 | AV13: 2025 | AW13: 2026 | AX13: TRUE | AY13: 12 | AZ13: 12 | BA13: 1 | BB13: 13
A14: 13 | B14: 20262 | C14: 11427.47 | D14: 9363.2163 | E14: -1.9058343 | F14: -2.3432434 | G14: -6.9045901 | H14: 1.7194855 | I14: 1.4283439 | J14: -7.2153418 | K14: 22.046419 | L14: FALSE | N14: 22.690182 | O14: 2.7567428 | P14: 49.518392 | Q14: 9908.84 | R14: 11765.397 | S14: 9265.1093 | T14: 0.84220196 | U14: 1.069479 | V14: 11.012717 | W14: 7.0384349 | X14: -1.3134793 | Y14: 2.3507006 | Z14: 9.554588 | AA14: 0.8367337 | AB14: 1.0237544 | AC14: 2224 | AD14: 5.7363941 | AG14: 55.084083 | AH14: 2109 | AI14: 5.4756749 | AJ14: 2380 | AK14: 6.1792823 | AL14: 2691 | AM14: 680 | AN14: 97.722263 | AO14: -29.240375 | AP14: -0.64376359 | AQ14: 0.65352465 | AR14: 4.4663676 | AS14: 2026Q2 | AT14: 2025 | AU14: 2024 | AV14: 2025 | AW14: 2026 | AX14: FALSE | AY14: 8 | AZ14: 7 | BA14: 11 | BB14: 7
A15: 14 | B15: 20262 | C15: 16783.491 | D15: 16722.657 | E15: 2.4213367 | F15: 0.65029658 | G15: -7.6346864 | H15: 1.3051898 | I15: -0.82738646 | J15: -14.193609 | K15: 0.36378587 | L15: FALSE | N15: -0.25266953 | O15: -12.082684 | P15: 5.9181201 | Q15: 11687.95 | R15: 16422.89 | S15: 16598.228 | T15: 0.71168656 | U15: 0.70416855 | V15: 7.5130633 | W15: 7.3400296 | X15: 1.4577762 | Y15: 1.6213276 | Z15: 9.0803631 | AA15: 0.74820683 | AB15: 0.72880252 | AC15: 24395 | AD15: 13.098676 | AE15: 24405 | AF15: 13.104045 | AG15: 57.027465 | AH15: 14399 | AI15: 7.7246404 | AJ15: 19844 | AK15: 10.645723 | AL15: 6528 | AM15: 6867 | AN15: -6.7828074 | AO15: -17.26506 | AP15: 0.6164554 | AQ15: -4.8810398 | AR15: -3.3800613 | AS15: 2026Q2 | AT15: 2025 | AU15: 2024 | AV15: 2025 | AW15: 2026 | AX15: FALSE | AY15: 17 | AZ15: 17 | BA15: 4 | BB15: 3
A16: 15 | B16: 20262 | C16: 14312.254 | D16: 12589.783 | E16: -4.7119982 | F16: -2.2731327 | G16: -17.491448 | H16: -0.2789898 | I16: -1.3611285 | J16: -11.091895 | K16: 13.681501 | L16: FALSE | N16: 8.3350317 | O16: -26.411446 | P16: 25.014636 | Q16: 10155.68 | R16: 14466.83 | S16: 12599.897 | T16: 0.70199758 | U16: 0.80601293 | V16: 2.8584696 | W16: 6.9500482 | X16: 4.755316 | Y16: 0.74770109 | Z16: 7.7497149 | AA16: 0.77380908 | AB16: 0.85041982 | AC16: 13194 | AD16: 19.589299 | AE16: 13958 | AF16: 20.723619 | AG16: 54.26246 | AH16: 5009 | AI16: 7.4478288 | AJ16: 7700 | AK16: 11.449048 | AL16: 2657 | AM16: 3182 | AN16: 1.2190476 | AO16: -8.5894858 | AP16: 5.346469 | AQ16: -9.2802601 | AR16: -5.2217607 | AS16: 2026Q2 | AT16: 2025 | AU16: 2024 | AV16: 2025 | AW16: 2026 | AX16: TRUE | AY16: 14 | AZ16: 15 | BA16: 3 | BB16: 1
A17: 16 | B17: 20262 | C17: 9457.8511 | D17: 8633.384 | E17: -0.81968429 | F17: 3.2157533 | G17: -12.551759 | H17: 6.9108333 | I17: 7.7493366 | J17: -4.9999276 | K17: 9.549755 | L17: FALSE | N17: 16.814756 | O17: 2.2536824 | P17: 27.985763 | Q17: 9302.48 | R17: 9350.7537 | S17: 8348.1411 | T17: 0.99483746 | U17: 1.1143175 | V17: -4.8012384 | W17: -0.52913472 | X17: 12.577532 | Y17: 7.7425194 | Z17: 7.1724163 | AA17: 1.0894957 | AB17: 1.1731235 | AC17: 1789 | AD17: 12.880975 | AG17: 56.082057 | AH17: 842 | AI17: 6.0680311 | AJ17: 1063 | AK17: 7.6607091 | AL17: 464 | AM17: 296 | AN17: -17.290553 | AO17: -25.440806 | AP17: -7.2650007 | AQ17: -8.6882634 | AR17: -5.0127709 | AS17: 2026Q2 | AT17: 2025 | AU17: 2024 | AV17: 2025 | AW17: 2026 | AX17: FALSE | AY17: 5 | AZ17: 4 | BA17: 10 | BB17: 17
A18: 17 | B18: 20262 | C18: 9945.4872 | D18: 8019.663 | E18: -1.0520383 | F18: -1.3342873 | G18: -6.4062736 | H18: -1.6521647 | I18: 0.72083012 | J18: -9.3490704 | K18: 24.01378 | L18: FALSE | N18: 27.586184 | O18: 13.04299 | P18: 62.860375 | Q18: 9374.53 | R18: 9844.4548 | S18: 8112.7801 | T18: 0.95226503 | U18: 1.1555262 | V18: 10.518097 | W18: 4.5798898 | X18: -1.6170881 | Y18: 3.969245 | Z18: 8.7309218 | AA18: 0.88492839 | AB18: 1.0856449 | AC18: 9633 | AD18: 14.849448 | AE18: 9679 | AF18: 14.920357 | AG18: 48.667892 | AH18: 7520 | AI18: 11.702641 | AJ18: 5792 | AK18: 9.0135234 | AL18: 3182 | AM18: 2602 | AN18: -27.118644 | AO18: 14.980115 | AP18: -3.5724042 | AQ18: 7.609275 | AR18: 6.4368517 | AS18: 2026Q2 | AT18: 2025 | AU18: 2024 | AV18: 2025 | AW18: 2026 | AX18: TRUE | AY18: 1 | AZ18: 3 | BA18: 7 | BB18: 5

Sheet src_dim_city
A1: city_id | B1: city_name | C1: teryt_code | D1: gus_name
A2: 1 | B2: Białystok | C2: 2061000 | D2: Powiat m. Białystok
A3: 2 | B3: Bydgoszcz | C3: 0461000 | D3: Powiat m. Bydgoszcz
A4: 3 | B4: Gdańsk | C4: 2261000 | D4: Powiat m. Gdańsk
A5: 4 | B5: Gdynia | C5: 2262000 | D5: Powiat m. Gdynia
A6: 5 | B6: Katowice | C6: 2469000 | D6: Powiat m. Katowice
A7: 6 | B7: Kielce | C7: 2661000 | D7: Powiat m. Kielce
A8: 7 | B8: Kraków | C8: 1261000 | D8: Powiat m. Kraków
A9: 8 | B9: Lublin | C9: 0663000 | D9: Powiat m. Lublin
A10: 9 | B10: Olsztyn | C10: 2862000 | D10: Powiat m. Olsztyn
A11: 10 | B11: Opole | C11: 1661000 | D11: Powiat m. Opole
A12: 11 | B12: Poznań | C12: 3064000 | D12: Powiat m. Poznań
A13: 12 | B13: Rzeszów | C13: 1863000 | D13: Powiat m. Rzeszów
... A18: 17 | B18: Łódź | C18: 1061000 | D18: Powiat m. Łódź

Sheet src_dim_nbp_period
A1: nbp_period_id | B1: nbp_period | C1: nbp_year | D1: nbp_quarter
A2: 20063 | B2: 2006Q3 | C2: 2006 | D2: 3
A3: 20064 | B3: 2006Q4 | C3: 2006 | D3: 4
A4: 20071 | B4: 2007Q1 | C4: 2007 | D4: 1
A5: 20072 | B5: 2007Q2 | C5: 2007 | D5: 2
A6: 20073 | B6: 2007Q3 | C6: 2007 | D6: 3
A7: 20074 | B7: 2007Q4 | C7: 2007 | D7: 4
A8: 20081 | B8: 2008Q1 | C8: 2008 | D8: 1
A9: 20082 | B9: 2008Q2 | C9: 2008 | D9: 2
A10: 20083 | B10: 2008Q3 | C10: 2008 | D10: 3
A11: 20084 | B11: 2008Q4 | C11: 2008 | D11: 4
A12: 20091 | B12: 2009Q1 | C12: 2009 | D12: 1
A13: 20092 | B13: 2009Q2 | C13: 2009 | D13: 2
... A81: 20262 | B81: 2026Q2 | C81: 2026 | D81: 2

Sheet src_dim_year
A1: year
A2: 2005
A3: 2006
A4: 2007
A5: 2008
A6: 2009
A7: 2010
A8: 2011
A9: 2012
A10: 2013
A11: 2014
A12: 2015
A13: 2016
... A23: 2026

Sheet src_fact_city_year
A1: city_id | B1: year | C1: avg_gross_monthly_wage_pln | D1: population_mid_year | E1: primary_annual_transaction_price_pln_m2 | F1: secondary_annual_transaction_price_pln_m2 | G1: primary_price_quarters_available | H1: secondary_price_quarters_available | I1: primary_affordability_m2 | J1: primary_annual_price_yoy_pct | K1: primary_affordability_yoy_pct | L1: secondary_affordability_m2 | M1: secondary_annual_price_yoy_pct | N1: secondary_affordability_yoy_pct | O1: wage_yoy_pct | P1: transactions | Q1: transaction_quarters_available | R1: sold_units | S1: sold_units_quarters_available | T1: sold_area_m2 | U1: sold_area_quarters_available | V1: avg_sold_area_m2 | W1: transactions_full_year_available | X1: sold_units_full_year_available | Y1: transactions_per_1000 | Z1: sold_units_per_1000 | AA1: completed | AB1: started | AC1: completed_months_available | AD1: started_months_available | AE1: started_full_year_available | AF1: completed_full_year_available | AG1: started_per_1000 | AH1: completed_per_1000 | AI1: completed_h1 | AJ1: started_h1 | AK1: completed_h1_months_available | AL1: started_h1_months_available | AM1: started_h1_yoy_pct | AN1: completed_h1_yoy_pct
A2: 1 | B2: 2005 | C2: 2365 | D2: 292138 | AA2: 1225 | AB2: 1338 | AC2: 12 | AD2: 12 | AE2: TRUE | AF2: TRUE | AG2: 4.5800272 | AH2: 4.1932238 | AI2: 383 | AJ2: 386 | AK2: 6 | AL2: 6
A3: 1 | B3: 2006 | C3: 2478.96 | D3: 295210 | AA3: 1219 | AB3: 1850 | AC3: 12 | AD3: 12 | AE3: TRUE | AF3: TRUE | AG3: 6.2667254 | AH3: 4.1292639 | AI3: 496 | AJ3: 540 | AK3: 6 | AL3: 6 | AM3: 39.896373 | AN3: 29.503916
A4: 1 | B4: 2007 | C4: 2715.96 | D4: 294817 | E4: 4413 | F4: 4029.6579 | G4: 4 | H4: 4 | I4: 0.61544528 | L4: 0.6739927 | AA4: 1667 | AB4: 1722 | AC4: 12 | AD4: 12 | AE4: TRUE | AF4: TRUE | AG4: 5.8409115 | AH4: 5.6543551 | AI4: 402 | AJ4: 608 | AK4: 6 | AL4: 6 | AM4: 12.592593 | AN4: -18.951613
A5: 1 | B5: 2008 | C5: 2994.05 | D5: 294265 | E5: 5112.75 | F5: 4410.5093 | G5: 4 | H5: 4 | I5: 0.58560462 | J5: 15.85656 | K5: -4.8486292 | L5: 0.67884451 | M5: 9.4512093 | N5: 0.71986029 | O5: 10.239105 | AA5: 1574 | AB5: 2058 | AC5: 12 | AD5: 12 | AE5: TRUE | AF5: TRUE | AG5: 6.9936962 | AH5: 5.3489202 | AI5: 628 | AJ5: 675 | AK5: 6 | AL5: 6 | AM5: 11.019737 | AN5: 56.218905
A6: 1 | B6: 2009 | C6: 3144.6 | D6: 294399 | E6: 4901.5 | F6: 4043.3258 | G6: 4 | H6: 4 | I6: 0.64155871 | J6: -4.1318273 | K6: 9.5549265 | L6: 0.7777261 | M6: -8.3251941 | N6: 14.566161 | O6: 5.0283061 | AA6: 1533 | AB6: 1300 | AC6: 12 | AD6: 12 | AE6: TRUE | AF6: TRUE | AG6: 4.4157759 | AH6: 5.2072188 | AI6: 483 | AJ6: 345 | AK6: 6 | AL6: 6 | AM6: -48.888889 | AN6: -23.089172
A7: 1 | B7: 2010 | C7: 3241.41 | D7: 293946 | E7: 4769.75 | F7: 4150.916 | G7: 4 | H7: 4 | I7: 0.6795765 | J7: -2.6879527 | K7: 5.9258476 | L7: 0.78089028 | M7: 2.660934 | N7: 0.40685095 | O7: 3.078611 | P7: 1491 | Q7: 4 | R7: 1496 | S7: 4 | T7: 80612.1 | U7: 4 | V7: 53.885094 | W7: TRUE | X7: TRUE | Y7: 5.0723602 | Z7: 5.0893702 | AA7: 1630 | AB7: 2075 | AC7: 12 | AD7: 12 | AE7: TRUE | AF7: TRUE | AG7: 7.0591197 | AH7: 5.5452362 | AI7: 736 | AJ7: 578 | AK7: 6 | AL7: 6 | AM7: 67.536232 | AN7: 52.380952
A8: 1 | B8: 2011 | C8: 3360.36 | D8: 294197 | E8: 4761.75 | F8: 4308.5613 | G8: 4 | H8: 4 | I8: 0.70569854 | J8: -0.16772368 | K8: 3.8438701 | L8: 0.77992624 | M8: 3.7978422 | N8: -0.1234543 | O8: 3.6696993 | P8: 1766 | Q8: 4 | R8: 1822 | S8: 4 | T8: 98722.1 | U8: 4 | V8: 54.18337 | W8: TRUE | X8: TRUE | Y8: 6.0027804 | Z8: 6.1931291 | AA8: 1711 | AB8: 1191 | AC8: 12 | AD8: 12 | AE8: TRUE | AF8: TRUE | AG8: 4.0483078 | AH8: 5.8158309 | AI8: 592 | AJ8: 485 | AK8: 6 | AL8: 6 | AM8: -16.089965 | AN8: -19.565217
A9: 1 | B9: 2012 | C9: 3493.98 | D9: 294675 | E9: 4456.25 | F9: 4050.3847 | G9: 4 | H9: 4 | I9: 0.78406283 | J9: -6.4157085 | K9: 11.104501 | L9: 0.86262917 | M9: -5.9921764 | N9: 10.603943 | O9: 3.9763597 | P9: 2045 | Q9: 4 | R9: 2056 | S9: 4 | T9: 107206.3 | U9: 4 | V9: 52.143142 | W9: TRUE | X9: TRUE | Y9: 6.939849 | Z9: 6.9771782 | AA9: 2249 | AB9: 2013 | AC9: 12 | AD9: 12 | AE9: TRUE | AF9: TRUE | AG9: 6.8312548 | AH9: 7.6321371 | AI9: 1074 | AJ9: 1148 | AK9: 6 | AL9: 6 | AM9: 136.70103 | AN9: 81.418919
A10: 1 | B10: 2013 | C10: 3627.02 | D10: 294925 | E10: 4514.25 | F10: 3900.7926 | G10: 4 | H10: 4 | I10: 0.80346015 | J10: 1.3015428 | K10: 2.4739498 | L10: 0.92981617 | M10: -3.6932821 | N10: 7.7886303 | O10: 3.8076921 | P10: 2090 | Q10: 4 | R10: 2069 | S10: 4 | T10: 108305.7 | U10: 4 | V10: 52.346883 | W10: TRUE | X10: TRUE | Y10: 7.0865474 | Z10: 7.0153429 | AA10: 1574 | AB10: 1324 | AC10: 12 | AD10: 12 | AE10: TRUE | AF10: TRUE | AG10: 4.4892769 | AH10: 5.3369501 | AI10: 403 | AJ10: 643 | AK10: 6 | AL10: 6 | AM10: -43.989547 | AN10: -62.476723
A11: 1 | B11: 2014 | C11: 3706.73 | D11: 295401 | E11: 4497.5 | F11: 3935.4661 | G11: 4 | H11: 4 | I11: 0.82417565 | J11: -0.37104724 | K11: 2.5782858 | L11: 0.94187827 | M11: 0.88888483 | N11: 1.297256 | O11: 2.1976719 | P11: 2399 | Q11: 4 | R11: 2412 | S11: 4 | T11: 122371.3 | U11: 4 | V11: 50.73437 | W11: TRUE | X11: TRUE | Y11: 8.1211641 | Z11: 8.1651721 | AA11: 1736 | AB11: 2031 | AC11: 12 | AD11: 12 | AE11: TRUE | AF11: TRUE | AG11: 6.8753999 | AH11: 5.8767574 | AI11: 860 | AJ11: 699 | AK11: 6 | AL11: 6 | AM11: 8.7091757 | AN11: 113.3995
A12: 1 | B12: 2015 | C12: 3844.68 | D12: 295624 | E12: 4566 | F12: 3928.0467 | G12: 4 | H12: 4 | I12: 0.84202365 | J12: 1.5230684 | K12: 2.1655578 | L12: 0.97877655 | M12: -0.18852686 | N12: 3.9175215 | O12: 3.7216091 | P12: 2441 | Q12: 4 | R12: 2448 | S12: 4 | T12: 121826.8 | U12: 4 | V12: 49.76585 | W12: TRUE | X12: TRUE | Y12: 8.2571104 | Z12: 8.2807891 | AA12: 2088 | AB12: 1893 | AC12: 12 | AD12: 12 | AE12: TRUE | AF12: TRUE | AG12: 6.4034043 | AH12: 7.063026 | AI12: 915 | AJ12: 359 | AK12: 6 | AL12: 6 | AM12: -48.640916 | AN12: 6.3953488
A13: 1 | B13: 2016 | C13: 3967.71 | D13: 296310 | E13: 4577.5 | F13: 3989.9963 | G13: 4 | H13: 4 | I13: 0.86678536 | J13: 0.25186159 | K13: 2.9407381 | L13: 0.99441446 | M13: 1.5771094 | N13: 1.5976994 | O13: 3.2000062 | P13: 2869 | Q13: 4 | R13: 2864 | S13: 4 | T13: 142836.3 | U13: 4 | V13: 49.87301 | W13: TRUE | X13: TRUE | Y13: 9.6824272 | Z13: 9.665553 | AA13: 1795 | AB13: 1514 | AC13: 12 | AD13: 12 | AE13: TRUE | AF13: TRUE | AG13: 5.1095137 | AH13: 6.0578448 | AI13: 875 | AJ13: 409 | AK13: 6 | AL13: 6 | AM13: 13.927577 | AN13: -4.3715847
A14: 1 | B14: 2017 | C14: 4164.59 | D14: 297132 | E14: 4587.25 | F14: 4105.502 | G14: 4 | H14: 4 | I14: 0.90786201 | J14: 0.21299836 | K14: 4.7389639 | L14: 1.0143924 | M14: 2.8948832 | N14: 2.0090144 | O14: 4.9620562 | P14: 3146 | Q14: 4 | R14: 3146 | S14: 4 | T14: 161938.1 | U14: 4 | V14: 51.474285 | W14: TRUE | X14: TRUE | Y14: 10.587887 | Z14: 10.587887 | AA14: 2033 | AB14: 2507 | AC14: 12 | AD14: 12 | AE14: TRUE | AF14: TRUE | AG14: 8.4373275 | AH14: 6.8420769 | AI14: 1086 | AJ14: 1326 | AK14: 6 | AL14: 6 | AM14: 224.20538 | AN14: 24.114286
A15: 1 | B15: 2018 | C15: 4396.32 | D15: 297403 | E15: 5183 | F15: 4552.0334 | G15: 4 | H15: 4 | I15: 0.84821918 | J15: 12.987084 | K15: -6.5695921 | L15: 0.96579257 | M15: 10.876413 | N15: -4.7910276 | O15: 5.5642932 | P15: 2982 | Q15: 4 | R15: 2992 | S15: 4 | T15: 150707.7 | U15: 4 | V15: 50.370221 | W15: TRUE | X15: TRUE | Y15: 10.026799 | Z15: 10.060423 | AA15: 1927 | AB15: 3438 | AC15: 12 | AD15: 12 | AE15: TRUE | AF15: TRUE | AG15: 11.560072 | AH15: 6.4794235 | AI15: 716 | AJ15: 1891 | AK15: 6 | AL15: 6 | AM15: 42.609351 | AN15: -34.069982
A16: 1 | B16: 2019 | C16: 4744.13 | D16: 297356 | E16: 5578.3173 | F16: 5182.2445 | G16: 4 | H16: 4 | I16: 0.85045897 | J16: 7.6271911 | K16: 0.26405823 | L16: 0.91545854 | M16: 13.844607 | N16: -5.2116808 | O16: 7.9113895 | P16: 3452 | Q16: 4 | R16: 3510 | S16: 4 | T16: 180151.7 | U16: 4 | V16: 51.325271 | W16: TRUE | X16: TRUE | Y16: 11.60898 | Z16: 11.804033 | AA16: 2450 | AB16: 2903 | AC16: 12 | AD16: 12 | AE16: TRUE | AF16: TRUE | AG16: 9.7627087 | AH16: 8.2392822 | AI16: 861 | AJ16: 2060 | AK16: 6 | AL16: 6 | AM16: 8.9370703 | AN16: 20.251397
A17: 1 | B17: 2020 | C17: 5126.79 | D17: 295302 | E17: 5823.2728 | F17: 5778.3057 | G17: 4 | H17: 4 | I17: 0.88039667 | J17: 4.3912081 | K17: 3.5201813 | L17: 0.88724796 | M17: 11.50199 | N17: -3.081579 | O17: 8.0659678 | P17: 3363 | Q17: 4 | R17: 3402 | S17: 4 | T17: 171883.9 | U17: 4 | V17: 50.524368 | W17: TRUE | X17: TRUE | Y17: 11.388341 | Z17: 11.52041 | AA17: 2832 | AB17: 3258 | AC17: 12 | AD17: 12 | AE17: TRUE | AF17: TRUE | AG17: 11.032773 | AH17: 9.5901823 | AI17: 1104 | AJ17: 1568 | AK17: 6 | AL17: 6 | AM17: -23.883495 | AN17: 28.222997
A18: 1 | B18: 2021 | C18: 5650.97 | D18: 294131 | E18: 6671.1237 | F18: 6291.392 | G18: 4 | H18: 4 | I18: 0.84707918 | J18: 14.559697 | K18: -3.7843727 | L18: 0.89820663 | M18: 8.8795273 | N18: 1.2351304 | O18: 10.224331 | P18: 4549 | Q18: 4 | R18: 4592 | S18: 4 | T18: 236576.2 | U18: 4 | V18: 51.519207 | W18: TRUE | X18: TRUE | Y18: 15.465898 | Z18: 15.612091 | AA18: 3234 | AB18: 3082 | AC18: 12 | AD18: 12 | AE18: TRUE | AF18: TRUE | AG18: 10.478324 | AH18: 10.995101 | AI18: 1440 | AJ18: 1878 | AK18: 6 | AL18: 6 | AM18: 19.770408 | AN18: 30.434783
A19: 1 | B19: 2022 | C19: 6183.98 | D19: 293028 | E19: 8338.4935 | F19: 7352.5927 | G19: 4 | H19: 4 | I19: 0.74161838 | J19: 24.993836 | K19: -12.449934 | L19: 0.84106114 | M19: 16.867502 | N19: -6.3621762 | O19: 9.432186 | P19: 3667 | Q19: 4 | R19: 3827 | S19: 4 | T19: 195585.8 | U19: 4 | V19: 51.10682 | W19: TRUE | X19: TRUE | Y19: 12.514162 | Z19: 13.060185 | AA19: 1979 | AB19: 1366 | AC19: 12 | AD19: 12 | AE19: TRUE | AF19: TRUE | AG19: 4.6616706 | AH19: 6.7536208 | AI19: 1207 | AJ19: 1071 | AK19: 6 | AL19: 6 | AM19: -42.971246 | AN19: -16.180556
A20: 1 | B20: 2023 | C20: 7089.31 | D20: 292058 | E20: 8701.2169 | F20: 7571.7266 | G20: 4 | H20: 4 | I20: 0.81474926 | J20: 4.3499871 | K20: 9.8609858 | L20: 0.93628711 | M20: 2.9803626 | N20: 11.322122 | O20: 14.639924 | Q20: 2 | R20: 3958 | S20: 4 | T20: 195474 | U20: 4 | V20: 49.387064 | W20: FALSE | X20: TRUE | Z20: 13.552103 | AA20: 2786 | AB20: 826 | AC20: 12 | AD20: 12 | AE20: TRUE | AF20: TRUE | AG20: 2.8282054 | AH20: 9.5392011 | AI20: 1633 | AJ20: 303 | AK20: 6 | AL20: 6 | AM20: -71.708683 | AN20: 35.294118
A21: 1 | B21: 2024 | C21: 8281.89 | D21: 290907 | E21: 10145.986 | F21: 8858.7569 | G21: 4 | H21: 4 | I21: 0.81627255 | J21: 16.604221 | K21: 0.18696438 | L21: 0.93488174 | M21: 16.997844 | N21: -0.15010071 | O21: 16.82223 | P21: 4395 | Q21: 4 | R21: 4402 | S21: 4 | T21: 216386 | U21: 4 | V21: 49.156293 | W21: TRUE | X21: TRUE | Y21: 15.107921 | Z21: 15.131984 | AA21: 2503 | AB21: 2855 | AC21: 12 | AD21: 12 | AE21: TRUE | AF21: TRUE | AG21: 9.814133 | AH21: 8.6041243 | AI21: 1513 | AJ21: 1229 | AK21: 6 | AL21: 6 | AM21: 305.61056 | AN21: -7.3484385
A22: 1 | B22: 2025 | C22: 9090.46 | D22: 289685 | E22: 10348.073 | F22: 9479.3216 | G22: 4 | H22: 4 | I22: 0.87846883 | J22: 1.9917958 | K22: 7.6195479 | L22: 0.95897791 | M22: 7.0050992 | N22: 2.577457 | O22: 9.7631096 | AA22: 1693 | AB22: 1891 | AC22: 12 | AD22: 12 | AE22: TRUE | AF22: TRUE | AG22: 6.5277802 | AH22: 5.8442791 | AI22: 1120 | AJ22: 1263 | AK22: 6 | AL22: 6 | AM22: 2.7664768 | AN22: -25.974884
A23: 1 | B23: 2026 | AI23: 311 | AJ23: 1351 | AK23: 6 | AL23: 6 | AM23: 6.9675376 | AN23: -72.232143
A24: 2 | B24: 2005 | C24: 2343.98 | D24: 367368 | AA24: 505 | AB24: 633 | AC24: 12 | AD24: 12 | AE24: TRUE | AF24: TRUE | AG24: 1.7230679 | AH24: 1.3746434 | AI24: 257 | AJ24: 38 | AK24: 6 | AL24: 6
A25: 2 | B25: 2006 | C25: 2482.78 | D25: 364953 | AA25: 681 | AB25: 1184 | AC25: 12 | AD25: 12 | AE25: TRUE | AF25: TRUE | AG25: 3.2442534 | AH25: 1.8659937 | AI25: 150 | AJ25: 475 | AK25: 6 | AL25: 6 | AM25: 1150 | AN25: -41.634241
A26: 2 | B26: 2007 | C26: 2690.84 | D26: 362397 | E26: 4039.25 | F26: 3634.3243 | G26: 4 | H26: 4 | I26: 0.66617318 | L26: 0.74039623 | AA26: 668 | AB26: 1243 | AC26: 12 | AD26: 12 | AE26: TRUE | AF26: TRUE | AG26: 3.4299401 | AH26: 1.8432824 | AI26: 414 | AJ26: 697 | AK26: 6 | AL26: 6 | AM26: 46.736842 | AN26: 176
A27: 2 | B27: 2008 | C27: 2973.85 | D27: 360142 | E27: 4735.25 | F27: 3841.0021 | G27: 4 | H27: 4 | I27: 0.62802386 | J27: 17.230922 | K27: -5.7266359 | L27: 0.77423806 | M27: 5.6868286 | N27: 4.5707729 | O27: 10.517534 | AA27: 1512 | AB27: 1604 | AC27: 12 | AD27: 12 | AE27: TRUE | AF27: TRUE | AG27: 4.4537988 | AH27: 4.198344 | AI27: 586 | AJ27: 1186 | AK27: 6 | AL27: 6 | AM27: 70.157819 | AN27: 41.545894
A28: 2 | B28: 2009 | C28: 3074.32 | D28: 358029 | E28: 4827.25 | F28: 3698.3685 | G28: 4 | H28: 4 | I28: 0.63686778 | J28: 1.9428752 | K28: 1.4082137 | L28: 0.83126383 | M28: -3.7134455 | N28: 7.3654046 | O28: 3.3784488 | AA28: 987 | AB28: 1131 | AC28: 12 | AD28: 12 | AE28: TRUE | AF28: TRUE | AG28: 3.158962 | AH28: 2.7567599 | AI28: 237 | AJ28: 416 | AK28: 6 | AL28: 6 | AM28: -64.924115 | AN28: -59.556314
A29: 2 | B29: 2010 | C29: 3184.45 | D29: 365202 | E29: 4735 | F29: 3809.6278 | G29: 4 | H29: 4 | I29: 0.67253432 | J29: -1.9110259 | K29: 5.6003048 | L29: 0.83589531 | M29: 3.0083334 | N29: 0.55716098 | O29: 3.5822556 | P29: 1782 | Q29: 4 | R29: 1595 | S29: 4 | T29: 83987.9 | U29: 4 | V29: 52.656991 | W29: TRUE | X29: TRUE | Y29: 4.8794913 | Z29: 4.367446 | AA29: 996 | AB29: 750 | AC29: 12 | AD29: 12 | AE29: TRUE | AF29: TRUE | AG29: 2.053658 | AH29: 2.7272578 | AI29: 619 | AJ29: 394 | AK29: 6 | AL29: 6 | AM29: -5.2884615 | AN29: 161.18143
A30: 2 | B30: 2011 | C30: 3363.68 | D30: 363607 | E30: 4641.5 | F30: 3774.7551 | G30: 4 | H30: 4 | I30: 0.72469676 | J30: -1.9746568 | K30: 7.7561006 | L30: 0.89109886 | M30: -0.91538267 | N30: 6.6041231 | O30: 5.6282875 | P30: 2411 | Q30: 4 | R30: 2206 | S30: 4 | T30: 114805.1 | U30: 4 | V30: 52.042203 | W30: TRUE | X30: TRUE | Y30: 6.6307854 | Z30: 6.0669899 | AA30: 865 | AB30: 1261 | AC30: 12 | AD30: 12 | AE30: TRUE | AF30: TRUE | AG30: 3.46803 | AH30: 2.3789421 | AI30: 171 | AJ30: 421 | AK30: 6 | AL30: 6 | AM30: 6.8527919 | AN30: -72.374798
A31: 2 | B31: 2012 | C31: 3468.51 | D31: 362286 | E31: 4580.75 | F31: 3560.59 | G31: 4 | H31: 4 | I31: 0.7571926 | J31: -1.3088441 | K31: 4.4840606 | L31: 0.97413911 | M31: -5.6736162 | N31: 9.3188597 | O31: 3.1165271 | P31: 2961 | Q31: 4 | R31: 2479 | S31: 4 | T31: 127027.2 | U31: 4 | V31: 51.241307 | W31: TRUE | X31: TRUE | Y31: 8.1731008 | Z31: 6.8426602 | AA31: 1023 | AB31: 837 | AC31: 12 | AD31: 12 | AE31: TRUE | AF31: TRUE | AG31: 2.3103294 | AH31: 2.8237359 | AI31: 468 | AJ31: 561 | AK31: 6 | AL31: 6 | AM31: 33.254157 | AN31: 173.68421
